<?xml version="1.0" ?>
<robot xmlns:xacro="http://www.ros.org/wiki/xacro" xmlns:xi="http://www.w3.org/2001/XInclude"
    xmlns:gazebo="http://playerstage.sourceforge.net/gazebo/xmlschema/#gz"
    xmlns:model="http://playerstage.sourceforge.net/gazebo/xmlschema/#model"
    xmlns:sensor="http://playerstage.sourceforge.net/gazebo/xmlschema/#sensor"
    xmlns:body="http://playerstage.sourceforge.net/gazebo/xmlschema/#body"
    xmlns:geom="http://playerstage.sourceforge.net/gazebo/xmlschema/#geom"
    xmlns:joint="http://playerstage.sourceforge.net/gazebo/xmlschema/#joint"
    xmlns:interface="http://playerstage.sourceforge.net/gazebo/xmlschema/#interface"
    xmlns:rendering="http://playerstage.sourceforge.net/gazebo/xmlschema/#rendering"
    xmlns:renderable="http://playerstage.sourceforge.net/gazebo/xmlschema/#renderable"
    xmlns:controller="http://playerstage.sourceforge.net/gazebo/xmlschema/#controller"
    xmlns:physics="http://playerstage.sourceforge.net/gazebo/xmlschema/#physics">
    <!-- BASE LINK -->
    <link name="base_link">

    <inertial>
        <mass value="0.1" />
        <origin xyz="0 0 0" />
        <!--inertia ixx="1.0" ixy="0.0" ixz="0.0"
               iyy="100.0" iyz="0.0" 
               izz="1.0" /-->
        <inertia ixx="1.0" ixy="0.0" ixz="0.0" iyy="1.0" iyz="0.0" izz="1.0" />
    </inertial>

    <visual>
        <origin xyz="0.0 0 0" rpy="0 0 0" />
        <geometry>
            <mesh filename="package://wsg_50_simulation/meshes/WSG50_110_w_adaptor.stl" scale="1 1 1" />
            <!--box size="0.146 0.05 0.0735"/-->
        </geometry>
        <material name="grey">
            <color rgba="0.5 0.5 0.5 1" />
        </material>
    </visual>
    <collision>
        <origin xyz="0.0 0 0" rpy="0 0 0" />
        <geometry>
            <!--box size="0.146 0.05 0.0735"/-->
            <mesh filename="package://wsg_50_simulation/meshes/WSG50_110_w_adaptor.stl" scale="1 1 1" />
        </geometry>
    </collision>
    </link>
    <gazebo reference="base_link">
        <material>Gazebo/Grey</material>
        <turnGravityOff>true</turnGravityOff>
    </gazebo>

    <link name="finger_left">

    <inertial>
        <mass value="0.1" />
        <origin xyz="0 0 0" />
        <inertia ixx="1.0" ixy="0.0" ixz="0.0" iyy="1.0" iyz="0.0" izz="1.0" />
    </inertial>

    <visual>
        <origin xyz="0.0 0 0" rpy="0 0 0" />
        <geometry>
            <mesh filename="package://wsg_50_simulation/meshes/peg_finger2.stl" scale="1 1 1" />
        </geometry>
        <material name="black">
            <color rgba="0 0 0 1" />
        </material>
    </visual>
    <collision>
        <origin xyz="0 0 0" rpy="0 0 0" />
        <geometry>
            <mesh filename="package://wsg_50_simulation/meshes/peg_finger2.stl" scale="1 1 1" />
        </geometry>
    </collision>
    </link>

    <!-- GRIPPER LEFT -->
    <joint name="base_joint_gripper_left" type="prismatic">
        <origin xyz="0 0 0" rpy="0 0 0" />      <!--origin xyz="-0.0067 0 0.049" rpy="0 0 0" /-->
        <parent link="base_link"/>
        <child link="gripper_left" />
        <dynamics friction="100" damping="100" />
        <axis xyz="1 0 0"/>
        <limit lower="-0.055" upper="-0.0031" effort="80" velocity="0.450"/>
    </joint>
    <link name="gripper_left">
    <inertial>
        <mass value="0.1" />
        <origin xyz="0.001 0.001 0.001" />
        <inertia ixx="1.0" ixy="0.0" ixz="0.0" iyy="1.0" iyz="0.0" izz="1.0" />
    </inertial>
    <visual>
        <origin xyz="0.0 0 0" rpy="0 0 0" />
        <geometry>
            <mesh filename="package://wsg_50_simulation/meshes/GUIDE_WSG50_110_scaled.stl" scale="1 1 1" />
            <!--box size="0.0175 0.03 0.024"/-->
        </geometry>
        <material name="black">
            <color rgba="0 0 0 1" />
        </material>
    </visual>
    <collision>
        <origin xyz="0 0 0" rpy="0 0 0" />
        <geometry>
            <!--box size="0.0175 0.03 0.024"/-->
            <mesh filename="package://wsg_50_simulation/meshes/GUIDE_WSG50_110_scaled.stl" scale="1 1 1" />
        </geometry>
    </collision>
    </link>
    <gazebo reference="gripper_left">
        <material>Gazebo/Blue</material>
        <turnGravityOff>true</turnGravityOff>
    </gazebo>
    <!-- LEFT FINGER -->
    <joint name="guide_joint_finger_left" type="fixed">
        <origin xyz="0 0 0.023" rpy="0 0 0" />
        <parent link="gripper_left" />
        <child link="finger_left" />
        <dynamics friction="1" damping="1" />
        <axis xyz="1 0 0" />
        <limit effort="80" velocity="0.450"/>
    </joint>
    
    <gazebo reference="finger_left">
        <material>Gazebo/Blue</material>
        <turnGravityOff>true</turnGravityOff>
    </gazebo>
    <!-- GRIPPER RIGHT -->
    <joint name="base_joint_gripper_right" type="prismatic">
        <limit lower="-0.055" upper="-0.0031" effort="80" velocity="0.450"/>
        <origin xyz="0 0 0" rpy="0 0 3.14159" />
        <parent link="base_link" />
        <child link="gripper_right" />
        <axis xyz="-1 0 0" />
        <dynamics friction="1" damping="1" />
        <mimic joint="base_joint_gripper_left" multiplier="-1" />
    </joint>

    <link name="gripper_right">
    <inertial>
        <mass value="0.1" />
        <origin xyz="0.001 0.001 0.001" />
        <inertia ixx="1.0" ixy="0.0" ixz="0.0" iyy="1.0" iyz="0.0" izz="1.0" />
    </inertial>
    <visual>
        <origin xyz="0.0 0 0" rpy="0 0 0" />
        <geometry>
            <mesh filename="package://wsg_50_simulation/meshes/GUIDE_WSG50_110_scaled.stl" scale="1 1 1" />
            <!--box size="0.0175 0.03 0.024"/-->
        </geometry>
        <material name="black">
            <color rgba="0 0 0 1" />
        </material>
    </visual>
    <collision>
        <origin xyz="0 0 0" rpy="0 0 0" />
        <geometry>
            <!--box size="0.0175 0.03 0.024"/-->
            <mesh filename="package://wsg_50_simulation/meshes/GUIDE_WSG50_110_scaled.stl" scale="1 1 1" />
        </geometry>
    </collision>
    </link>
    <gazebo reference="gripper_right">
        <material>Gazebo/White</material>
        <turnGravityOff>true</turnGravityOff>
    </gazebo>
    <!-- RIGHT FINGER -->
    <joint name="guide_joint_finger_right" type="fixed">
        <origin xyz="0 0 0.023" rpy="0 0 0" />
        <parent link="gripper_right" />
        <child link="finger_right" />
        <dynamics friction="100" damping="100" />
        <axis xyz="1 0 0" />
        <limit effort="80" velocity="0.450" />
    </joint>
    <link name="finger_right">
    <inertial>
        <mass value="0.1" />
        <origin xyz="0 0 0" />
        <inertia ixx="1.0" ixy="0.0" ixz="0.0" iyy="1.0" iyz="0.0" izz="1.0" />
    </inertial>
    <visual>
        <origin xyz="0.0 0 0" rpy="0 0 0" />
        <geometry>
            <mesh filename="package://wsg_50_simulation/meshes/peg_finger2.stl" scale="1 1 1" />
        </geometry>
        <material name="black">
            <color rgba="0 0 0 1" />
        </material>
    </visual>
    <collision>
        <origin xyz="0 0 0" rpy="0 0 0" />
        <geometry>
            <mesh filename="package://wsg_50_simulation/meshes/peg_finger2.stl" scale="1 1 1" />
        </geometry>
    </collision>
    </link>
    <gazebo reference="finger_right">
        <material>Gazebo/White</material>
        <turnGravityOff>true</turnGravityOff>
    </gazebo>
   
    
    <transmission name="trans_base_joint_gripper_left">
        <robotNamespace>/iiwa</robotNamespace>
        <type>transmission_interface/SimpleTransmission</type>
        <joint name="base_joint_gripper_left">
            <hardwareInterface>hardware_interface/PositionJointInterface</hardwareInterface>
        </joint>
        <actuator name="base_joint_gripper_left_motor">
            <hardwareInterface>hardware_interface/PositionJointInterface</hardwareInterface>
            <mechanicalReduction>1</mechanicalReduction>
        </actuator>
    </transmission>
    <!-- <transmission name="trans_base_joint_gripper_right">
        <robotNamespace>/iiwa</robotNamespace>
        <type>transmission_interface/SimpleTransmission</type>
        <joint name="base_joint_gripper_right">
            <hardwareInterface>hardware_interface/PositionJointInterface</hardwareInterface>
        </joint>
        <actuator name="base_joint_gripper_right_motor">
            <hardwareInterface>hardware_interface/PositionJointInterface</hardwareInterface>
            <mechanicalReduction>1</mechanicalReduction>
        </actuator>
    </transmission> -->
    
    <gazebo>
    <plugin name="mimic_joint_plugin" filename="libroboticsgroup_gazebo_mimic_joint_plugin.so">
        <joint>base_joint_gripper_left</joint>
        <mimicJoint>base_joint_gripper_right</mimicJoint>
        <multiplier>-1</multiplier>
        <hasPID />
        <offset>0</offset>
        <sensitiveness>0.0</sensitiveness>   <!-- if absolute difference between setpoint and process value is below this threshold, do nothing; 0.0 = disable [rad] -->
        <maxEffort>80</maxEffort>              <!-- only taken into account if has_pid:=true [Nm] -->
        <robotNamespace>/iiwa</robotNamespace>
    </plugin>
    </gazebo>

</robot>